<?xml version="1.0" encoding="utf-8"?>
<!-- This URDF was automatically created by SolidWorks to URDF Exporter! Originally created by Stephen Brawner (brawner@gmail.com) 
     Commit Version: 1.5.1-0-g916b5db  Build Version: 1.5.7152.31018
     For more information, please see http://wiki.ros.org/sw_urdf_exporter -->
<robot name="manipulator">
	<link name="world">
   </link>
	<link name="link_0">
		<inertial>
			<!-- <origin xyz="-0.0021206 0.0002459 0.064773" rpy="0 0 0" /> -->
			<mass value="0.09286" />
			<inertia ixx="5.326E-05" ixy="-1.315E-07" ixz="-2.2253E-08" iyy="5.6454E-05" iyz="-6.8881E-23" izz="8.948E-05" /> 
			<!-- <mass value="0.0"/> -->
			<!-- <inertia ixx="0.0" ixy="0.0" ixz="0.0" iyy="0.0" iyz="0.0" izz="0.0"/> -->
		</inertial>
		<visual>
			<origin xyz="0 0 0" rpy="0 0 0" />
			<geometry>
				<mesh filename="package://simulation_rviz/meshes/link_0.STL" />
			</geometry>
			<material name="">
				<color rgba="0.79216 0.81961 0.93333 1" />
			</material>
		</visual>
		<collision>
			<origin xyz="0 0 0" rpy="0 0 0" />
			<geometry>
				<mesh filename="package://simulation_rviz/meshes/link_0.STL" />
			</geometry>
		</collision>
	</link>
	<joint name="dummy_joint" type="fixed">
     <parent link="world"/>
     <child link="link_0"/>
   </joint>
	<link name="link_1">
		<inertial>
			<origin xyz="-1.4162E-05 0.0091539 0.0097543" rpy="0 0 0" />
			<mass value="0.021123" />
			<inertia ixx="3.515E-06" ixy="2.2398E-16" ixz="-1.8348E-15" iyy="7.5839E-06" iyz="2.8002E-09" izz="7.0937E-06" />
		</inertial>
		<visual>
			<origin xyz="0 0 0" rpy="0 0 0" />
			<geometry>
				<mesh filename="package://simulation_rviz/meshes/link_1.STL" />
			</geometry>
			<material name="">
				<color rgba="0.79216 0.81961 0.93333 1" />
			</material>
		</visual>
		<collision>
			<origin xyz="0 0 0" rpy="0 0 0" />
			<geometry>
				<mesh filename="package://simulation_rviz/meshes/link_1.STL" />
			</geometry>
		</collision>
	</link>
	<joint name="joint_1" type="revolute">
		<origin xyz="0.0029256 -5.3727E-05 0.1232" rpy="0 0 0.011222" />
		<parent link="link_0" />
		<child link="link_1" />
		<axis xyz="0 0 1" />
		<limit lower="0.0" upper="3.14159265359" effort="1.0" velocity="1.0"/>
	</joint>
	<link name="link_2">
		<inertial>
			<origin xyz="0.040762 9.3746E-11 0.00077048" rpy="0 0 0" />
			<mass value="0.016936" />
			<inertia ixx="1.0452E-06" ixy="1.6239E-15" ixz="-2.8002E-09" iyy="1.958E-05" iyz="2.8964E-16" izz="2.0421E-05" />
		</inertial>
		<visual>
			<origin xyz="0 0 0" rpy="0 0 0" />
			<geometry>
				<mesh filename="package://simulation_rviz/meshes/link_2.STL" />
			</geometry>
			<material name="">
				<color rgba="0.64706 0.51765 0 1" />
			</material>
		</visual>
		<collision>
			<origin xyz="0 0 0" rpy="0 0 0" />
			<geometry>
				<mesh filename="package://simulation_rviz/meshes/link_2.STL" />
			</geometry>
		</collision>
	</link>
	<joint name="joint_2" type="revolute">
		<origin xyz="-0.00029839 0.01004 0.039318" rpy="1.5708 0.0098142 0" />
		<parent link="link_1" />
		<child link="link_2" />
		<axis xyz="0 0 1" />
		<limit lower="0.0" upper="3.14159265359" effort="1.0" velocity="0.0"/>
	</joint>
	<link name="link_3">
		<inertial>
			<origin xyz="0.01702 0.00029705 -0.0010045" rpy="0 0 0" />
			<mass value="0.0089186" />
			<inertia ixx="2.3882E-07" ixy="-7.0517E-08" ixz="5.0478E-20" iyy="4.278E-06" iyz="-3.9823E-20" izz="4.3426E-06" />
		</inertial>
		<visual>
			<origin xyz="0 0 0" rpy="0 0 0" />
			<geometry>
				<mesh filename="package://simulation_rviz/meshes/link_3.STL" />
			</geometry>
			<material name="">
				<color rgba="0.50196 0.50196 0.50196 1" />
			</material>
		</visual>
		<collision>
			<origin xyz="0 0 0" rpy="0 0 0" />
			<geometry>
				<mesh filename="package://simulation_rviz/meshes/link_3.STL" />
			</geometry>
		</collision>
	</link>
	<joint name="joint_3" type="revolute">
		<origin xyz="0.1199 0 0.01365" rpy="0 0 -1.57079632679" />
		<parent link="link_2" />
		<child link="link_3" />
		<axis xyz="0 0 1" />
		<limit lower="0.0" upper="3.14159265359" effort="1.0" velocity="0.0"/>
	</joint>

	<link name="link_4">
		<inertial>
			<origin xyz="0.01702 0.00029705 -0.0010045" rpy="0 0 0" />
			<mass value="0.0089186" />
			<inertia ixx="2.3882E-07" ixy="-7.0517E-08" ixz="5.0478E-20" iyy="4.278E-06" iyz="-3.9823E-20" izz="4.3426E-06" />
		</inertial>
		<visual>
			<origin xyz="0 0 0" rpy="0 0 0" />
			<geometry>
				<cylinder radius="0" length="0"/>
			</geometry>
			<material name="">
				<color rgba="0.50196 0.50196 0.50196 1" />
			</material>
		</visual>
		<collision>
			<origin xyz="0 0 0" rpy="0 0 0" />
			<geometry>
				<cylinder radius="0" length="0"/>
			</geometry>
		</collision>
	</link>

	<joint name="joint_4" type="fixed">
		<origin xyz="0.0899 0.002 0.0037" rpy="0 0 0" />
		<parent link="link_3" />
		<child link="link_4" />
	</joint>
	<gazebo>
    	<plugin name="gazebo_ros_control" filename="libgazebo_ros_control.so">
      		<robotNamespace>/manipulator</robotNamespace>
    	</plugin>
  	</gazebo>
	<transmission name="joint_1_trans">
		<type>transmission_interface/SimpleTransmission</type>
		<joint name="joint_1">
			<hardwareInterface>hardware_interface/EffortJointInterface</hardwareInterface>
		</joint>
		<actuator name="joint_1_motor">
			<mechanicalReduction>2</mechanicalReduction>
			<hardwareInterface>hardware_interface/EffortJointInterface</hardwareInterface>
		</actuator>
	</transmission>
	<transmission name="joint_2_trans">
		<type>transmission_interface/SimpleTransmission</type>
		<joint name="joint_2">
			<hardwareInterface>hardware_interface/EffortJointInterface</hardwareInterface>
		</joint>
		<actuator name="joint_2_motor">
			<mechanicalReduction>2</mechanicalReduction>
			<hardwareInterface>hardware_interface/EffortJointInterface</hardwareInterface>
		</actuator>
	</transmission>
	<transmission name="joint_3_trans">
		<type>transmission_interface/SimpleTransmission</type>
		<joint name="joint_3">
			<hardwareInterface>hardware_interface/EffortJointInterface</hardwareInterface>
		</joint>
		<actuator name="joint_3_motor">
			<mechanicalReduction>2</mechanicalReduction>
			<hardwareInterface>hardware_interface/EffortJointInterface</hardwareInterface>
		</actuator>
	</transmission>
	<!-- <transmission name="joint_4_trans">
			<type>transmission_interface/SimpleTransmission</type>
			<joint name="joint_4">
				<hardwareInterface>hardware_interface/EffortJointInterface</hardwareInterface>
			</joint>
			<actuator name="joint_4_motor">
				<mechanicalReduction>2</mechanicalReduction>
				<hardwareInterface>hardware_interface/EffortJointInterface</hardwareInterface>
			</actuator>
	</transmission> -->
  <!-- ROS Control plugin for Gazebo -->
  
</robot>